Workbook

Sheet PETUNJUK
A1: TEMPLATE DATABASE & REKAP STATISTIK UMAT PAROKI ST. KLEMENT I SEPINGGAN BALIKPAPAN — 2026
A3: 1 | B3: Dasar | C3: Struktur rekap mengikuti PDF Statistik Paroki St. Klement I Balikpapan 2026: perkembangan jumlah umat, baptis, pindah agama, Komuni Pertama, perkawinan, pembubaran, perminyakan suci, kematian, dan seminari/biara.
A4: 2 | B4: Cara kerja | C4: Satu baris DATA UMAT = satu orang. Peristiwa tahunan dicatat pada sheet kejadian. Sheet REKAP LINGKUNGAN dan REKAP DETAIL menghitung otomatis.
A5: 3 | B5: Atribut wajib | C5: ID Umat, ID KK, Nama, Jenis Kelamin, Tanggal Lahir, Agama, Lingkungan, Basis/Stasi/Daerah, dan Status Umat.
A6: 4 | B6: Kenaikan umat | C6: BAPTIS, DITERIMA MASUK, dan MUTASI (Masuk) dipakai untuk bagian 1.1.
A7: 5 | B7: Pengurangan umat | C7: KEMATIAN, MUTASI (Keluar), dan PINDAH AGAMA dipakai untuk bagian 1.2.
A8: 6 | B8: Baptis | C8: Tanggal baptis + tanggal lahir + jenis kelamin memungkinkan rekap umur: <1 tahun; 1 s/d hampir 7 tahun; 7 tahun ke atas.
A9: 7 | B9: Pindah agama | C9: Agama baru direkap menjadi Kristen Lain, Buddha, Konghucu, Islam, Hindu, Lain-lain.
A10: 8 | B10: Kejadian sakramen | C10: Komuni Pertama, Perkawinan Gerejani, Pembubaran, Perminyakan Suci, Kematian, dan Seminari/Biara memiliki sheet khusus.
A11: 9 | B11: Per lingkungan | C11: Isi nama lingkungan pada kolom A REKAP LINGKUNGAN. Tidak perlu mengetik angka rekap.
A12: 10 | B12: Catatan | C12: PDF mencantumkan tenggat pengembalian 26 Januari 2025 pada bagian akhir, sedangkan judul statistik adalah 2026. Template ini tidak mengubah/menafsirkan tanggal tersebut; periode statistik otomatis tetap 1 Jan–31 Des 2026.

Sheet LIST
A1: Gender | B1: Agama | C1: Status Umat | D1: Jenis Mutasi | E1: Rute Mutasi | F1: Jenis Perkawinan | G1: Pembubaran | H1: Jalur Seminari/Biara | I1: Status Seminari
A2: Pria/Laki-laki | B2: Katolik | C2: Aktif | D2: Masuk | E2: Paroki lain dalam keuskupan | F2: Keduanya Katolik | G2: Penguasa Gereja | H2: Seminari Menengah | I2: Mulai masuk 2026
A3: Wanita/Perempuan | B3: Kristen Lain | C3: Meninggal | D3: Keluar | E3: Keuskupan lain | F3: Katolik dan Katekumen | G3: Catatan Sipil saja | H3: Seminari Tinggi/Frater | I3: Sedang belajar 2026
B4: Islam | C4: Pindah Keluar | F4: Katolik dan Kristen Lain | G4: Lainnya | H4: Biara/Novisiat Bruder
B5: Hindu | C5: Pindah Agama | F5: Katolik dan Non-Kristen | H5: Biara/Novisiat Suster
B6: Buddha
B7: Konghucu
B8: Lain-lain
B11: St. Andreas Rasul
B12: St. Fransiskus Asisi
B13: St. Maria Ratu Rosari
B14: St. Albertus
B15: St. Maria Salve Regina
B16: St. Anna
B17: St. Clara
B18: St. Monica
B19: St. Theresia dari Lisieux
... B27: Stasi Handil

Sheet DATA KK
A1: ID KK | B1: Nama KK | C1: Alamat | D1: Kelurahan | E1: Lingkungan | F1: Basis/Stasi | G1: Telp/HP | H1: Email | I1: Status Perkawinan | J1: Tanggal Input | K1: Keterangan
A2: 1 | B2: Agnes Sri Subekti | C2: Jln prona 3 Sepinggan | D2: Sepinggan | G2: 085246233033 | H2: Srisubekti378@gmail.com | I2: Menikah
A3: 2 | B3: Albertus Benny Bimo Atmojo | C3: Jln prona 3 sepinggan | D3: sepinggan | G3: 081806753957 | I3: Lajang
A4: 3 | B4: ALFONS VICKY DANIELS | C4: Jl. Sepinggan baru | D4: Balikpapan selatan | G4: 08111149938 | H4: alfonsvickydaniels@gmail.com | I4: Lajang
A5: 4 | B5: Andi putra lubis | C5: Jln.marma r Iswahyudi RT 9 no 42 | D5: Sepinggan raya | G5: 081256607766 | H5: ardelina1373@gmail.com | I5: Menikah
A6: 5 | B6: Angelina Arista Jeli | C6: Jalan Mulawarman 13 | D6: Sepinggan | G6: 085330335006 | H6: angelinajeli287@gmail.com | I6: Lajang
A7: 6 | B7: anthanosius koen broto driyatmo | C7: Jl. Prona III perum bukit prona indah blok v/9 | D7: sepinggan | G7: 082154222442 | H7: koenbroto@gmail.com | I7: Menikah
A8: 7 | B8: Arthur anthonius runtu | C8: Lamaru Rt 23 no 17 | D8: Lamaru | G8: 082351343230 | H8: Selfanicc@gmail.com | I8: Lajang
A9: 8 | B9: Barin Pradana | C9: jl.jend sudirman | D9: damai | G9: 081346305051 | H9: Sukawatidiana@gmail.com | I9: Menikah
A10: 9 | B10: Casey matthew cozlov maengkom | C10: Jl. Gn guntur asri no.37 rt 35 | D10: Gunung sari ulu | G10: 082351343230 | H10: Selfanicc@gmail.com | I10: Janda
A11: 10 | B11: Christian kusuma | C11: Jl Jend Sudirman blok A no 27 | D11: Klandasan ulu | G11: 0811545078 | H11: Christiankodok@yahoo.com | I11: Menikah
A12: 11 | B12: Densius Christian Naga | C12: Jln.Marsma Iswahyudi No.1, Rt 10 | D12: Kelurahan Sepinggan Raya | G12: 081270098588 | H12: Barbarafenyodjan@gmail.com | I12: Menikah
A13: 12 | B13: Elisabeth Mantiri | C13: Jl.Mulawarman Rt 23 No.17 | D13: Lamaru | G13: 082351343230 | H13: Selfanicc@gmail.com | I13: Janda
A14: 13 | B14: Endang Yudhaningsih | C14: Jl. Syarifuddin Yoes No.10 RT.01 | D14: Sepinggan Baru | G14: 085716012223 | H14: - | I14: Janda
A15: 14 | B15: Febrianty Anastasia Malau | C15: Jl.Mulawarman Rt.10 | D15: Sepinggan | G15: 082122242908 | H15: agnesmonica2170@gmail.com | I15: Lajang
A16: 15 | B16: Hadi Sujono | C16: Jl Teratai Merah No 51 RT 056 | D16: Sepinggan | G16: 085347992266 | I16: Menikah
A17: 16 | B17: HARIYOTEJO DWINANTO | C17: Jl. Syarifuddin Yoes No.10 RT.01 | D17: Sepinggan Baru | G17: 081548607099 | H17: dhwidodo@yahoo.com | I17: Lajang
A18: 17 | B18: Hipolitus kanisius bogar | C18: Jln gang Tirtosari | D18: Sepinggan | G18: 081351595667 | H18: Chievocaprio99@gmail.com | I18: Lajang
A19: 18 | B19: IGNATIUS BUDIARIYANTO | C19: PERUM PALM HILLS CLUSTER PAVILION BLOK B NO.6 RT 7 | D19: SEPINGGAN | G19: 081578757836 | H19: ignatius.budiariyanto@gmail.com | I19: Menikah
A20: 19 | B20: IGNATIUS SUYATO | C20: Jl. Marsma R iswahyudi RT 15 | D20: Sepinggan | G20: 085234025605 | H20: ignasiuscm@gmail.com | I20: Menikah
A21: 20 | B21: Janson Saragih | C21: Jl Tetapi Merah Rt 31 No 31 Sepinggan | D21: Sepinggan | G21: 08126328520 | H21: fenesiasiska@gmail.com | I21: Menikah
A22: 21 | B22: JOSEPH KUMARURUNG | C22: APT Puri Garden Unit 310 | D22: Kembangan Selatan | G22: 085225252937 | I22: Menikah
A23: 22 | B23: La mbirita tadiyus | C23: Jln, Marsma r Iswahyudi | D23: Sepinggan | G23: 081253212457 | I23: Menikah
A24: 23 | B24: Lusia yulmia | C24: Jl. Jend. Sudirman no 107 | D24: Damai | G24: 081253330525 | H24: luciayulmia@gmail.com | I24: Kawin Belum Tercatat
A25: 24 | B25: MARIA AFIA DEU GHOLO | C25: Jl.mulawarman no.10 | D25: Sepinggan | G25: 082266416706 | H25: - | I25: Lajang
A26: 25 | B26: Maria Emakulata Mei | C26: Jl. Wiyata No 33 RT 022 | D26: Sepinggan Raya | G26: 085245469420 | H26: emakulatamei@gmail.com | I26: Lajang
A27: 26 | B27: MARIA SRITANTI HADIM | C27: Jl.MT.HaryonoNo.069 RT.05 | D27: DAMAI BAHAGIA | G27: 081350553136 | H27: mariasri02@gmail.com | I27: Menikah
A28: 27 | B28: MARKUS HENDRIK | C28: Jl.marsma r.iswahyudi no.8 | D28: Sepinggan raya | G28: 081346435198 | I28: Menikah
A29: 28 | B29: Martinus Apriadi Putra | C29: Jl Mayjend Sutoyo | D29: Klandasan Ilir | G29: 087840453320 | H29: septinuel@gmail.com | I29: Menikah
A30: 29 | B30: MARTINUS PRASETYO ADI NUGROHO | C30: PERUM PALM HILLS CITY GARDEN VILLA NO 32 RT 08 | D30: SEPINGGAN | G30: 081229888001 | H30: martinuspa@gmail.com | I30: Menikah
A31: 30 | B31: Martinus Suratmin | C31: Jl. Marsma R. Iswahyudi No. 399 Rt. 12 | D31: Sepinggan Raya | G31: 081346450297 | H31: patrisialidya@gmail.com | I31: Duda
A32: 31 | B32: Petrus Ua | C32: Jl Mulawarman RT 012 | D32: Sepinggan | I32: Menikah
A33: 32 | B33: Polonius Dosi Miten | C33: Jl Teratai Merah No 51 RT 056 | D33: Sepinggan | G33: 081254771052 | H33: dina.wulandari13@gmail.com | I33: Menikah
A34: 33 | B34: Ryoga Adityo Dipowikoro | C34: Jl. Margasatwa Barat No. 5 Bukit Indah Residence Kav 7. | D34: Cilandak Timur | G34: 0811599500 | H34: r.dipowikoro@gmail.com | I34: Lajang
A35: 34 | B35: Saut Parlindungan Sitanggang | C35: Perum Regalia Residence | D35: Sepinggan | G35: 081255056902 | H35: Horasbersaudara77@gmail.com | I35: Menikah
A36: 35 | B36: SERVINUS | C36: ASRAMA POLISI JLN. KEMUNING | D36: SUKARAME | G36: 081343674806 | H36: Ajuseceryl@yahoo.com | I36: Lajang
A37: 36 | B37: Simon Santi | C37: Gunung Guntur | D37: Sumber rejo | G37: 082155686618 | H37: Simonsanti64 Gmail de com | I37: Menikah
A38: 37 | B38: Thomas Sakino | C38: Jln prona 3 sepinggan | D38: Sepinggan | G38: 081345459244 | I38: Menikah
A39: 38 | B39: Willis saputra | C39: Jl. Kok Syarifuddin Yoes komp central bizpark 2 | D39: Sepinggan baru | G39: 082284081405 | H39: Williscmp24@gmail.com | I39: Menikah
A40: 39 | B40: YOHANES WASKITO | C40: Jln. Marsma R Iswahyudi Gang Mawar RT 04 | D40: Sepinggan Raya | G40: 085647323103 | H40: yohan.waskito@gmail.com | I40: Menikah
...

Sheet DATA UMAT
A1: ID Umat | B1: ID KK | C1: Nama Lengkap | D1: Jenis Kelamin | E1: Tanggal Lahir | F1: Umur 31/12/2026 | G1: Agama | H1: Lingkungan | I1: Basis/Stasi | J1: Daerah/Desa | K1: Status Umat | L1: Tanggal Baptis | M1: Paroki/Gereja Baptis | N1: No Buku Baptis | O1: Tanggal Komuni I | P1: Paroki/Gereja Komuni I | Q1: Tanggal Krisma | R1: Paroki/Gereja Krisma | S1: Pendidikan Terakhir | T1: Profesi | U1: Golongan Darah | V1: NIK (opsional) | W1: No KK (opsional) | X1: Telp/HP | Y1: Email | Z1: Keterangan
A2: 1 | B2: 6471055507570003 | C2: Agnes Sri Subekti | D2: Wanita | E2: 21016 | G2: Katolik | K2: Masih Hidup | M2: Muntilan | N2: 13 No 13278 | S2: SLTA/SMA | T2: Pensiunan | U2: B | V2: 6471055507570003 | W2: 6471055507570003 | X2: 085246233033 | Y2: Srisubekti378@gmail.com
A3: 2 | B3: 6471051007060015 | C3: Agnes Sri Subekti | D3: Wanita | E3: 21016 | G3: Katolik | K3: Masih Hidup | M3: Muntilan | N3: Buku 13 no. 13278 | S3: SLTA/SMA | T3: Pensiun PNS | U3: B | V3: 6471055507570003 | W3: 6471051007060015 | X3: 085246233033 | Y3: Srisubekti378@gmail.com
A4: 3 | B4: 6471051097060015 | C4: Albertus Benny Bimo Atmojo | D4: Pria | E4: 30970 | G4: Katolik | K4: Masih Hidup | M4: Santa Theresia Balikpapan | N4: no III /98/3004 | S4: D3 | T4: Pegawai swasta | U4: O | V4: 6471050510840001 | W4: 6471051097060015 | X4: 081806753957
A5: 4 | B5: 6471052409210016 | C5: ALFONS VICKY DANIELS | D5: Pria | E5: 33247 | G5: Katolik | K5: Masih Hidup | M5: Gereja katolik St. Martinus sepinggan | S5: SLTA/SMA | T5: Karyawan swasta | U5: O | V5: 6471050901900002 | W5: 6471052409210016 | X5: 08111149938 | Y5: alfonsvickydaniels@gmail.com
A6: 5 | B6: 6471050204180019 | C6: Andi putra lubis | D6: Pria | E6: 30681 | G6: Katolik | K6: Masih Hidup | M6: Santo fidelis | N6: Muara II | S6: SLTA/SMA | T6: Buruh | U6: O | V6: 6472053112830060.0 | W6: 6471050204180019 | X6: 081256607766 | Y6: ardelina1373@gmail.com
A7: 6 | B7: 6471051910220016 | C7: Angelina Arista Jeli | D7: Wanita | E7: 34908 | G7: Katolik | K7: Masih Hidup | M7: Santa Maria Penolong Abadi Lawir | S7: S1 | T7: Guru | U7: Tidak tahu | V7: 5319026807950003 | W7: 6471051910220016 | X7: 085330335006 | Y7: angelinajeli287@gmail.com
A8: 7 | B8: 6471050901140019 | C8: ANGELINA MARIA INAR PRADANTI | D8: Wanita | E8: 31799 | G8: Katolik | K8: Masih Hidup | M8: SANTA MARIA FATIMA MAGELANG | N8: III | S8: S1 | T8: KARYAWAN SWASTA | U8: A | V8: 3371026201870003 | W8: 6471050901140019 | X8: 081328197225 | Y8: inarpradanti@gmail.com
A9: 8 | B9: 6471052707100031 | C9: Anita yusdiyani | D9: Wanita | E9: 41874 | G9: Katolik | K9: Masih Hidup | M9: St, Klemens 1 Balikpapan | N9: 1 hal, 133 | S9: SD | U9: A | V9: 7471056308140003 | W9: 6471052707100031 | X9: 081253212457
A10: 9 | B10: 6471052011090035 | C10: ANJELINA AGATHA | D10: Wanita | E10: 41624 | G10: Katolik | K10: Masih Hidup | M10: SANTO KLEMENS 1 BALIKPAPAN | N10: I | S10: SD | U10: Tidak tahu | V10: 6471055612130002 | W10: 6471052011090035
A11: 10 | B11: 6471051803090046 | C11: anthanosius koen broto driyatmo | D11: Pria | E11: 28977 | G11: Katolik | K11: Masih Hidup | M11: yohanes rasul wonogiri | S11: S1 | T11: guru | U11: B | V11: 6471050205790010.0 | W11: 6471051803090046 | X11: 082154222442 | Y11: koenbroto@gmail.com
A12: 11 | B12: 6471051007060015 | C12: Antonius Dicky Permadi | D12: Pria | E12: 35839 | G12: Katolik | K12: Masih Hidup | M12: Santa Theresia Balikpapan | N12: V/32/315 | S12: D4 | T12: kuliah | U12: B | V12: 64711050302980008 | W12: 6471051007060015 | X12: 88905224206.0
A13: 12 | B13: 6471050204180019 | C13: Ardelina sinaga | D13: Wanita | E13: 30046 | G13: Protestan | K13: Masih Hidup | S13: SLTA/SMA | T13: Ibu rumah tangga | U13: A | V13: 1208294504820002 | W13: 6471050204180019 | X13: 081256607766 | Y13: ardelina1373@gmail.com
A14: 13 | B14: 6471015812520001 | C14: Arthur anthonius runtu | D14: Pria | E14: 27269 | G14: Katolik | K14: Masih Hidup | M14: Santa theresia prapatan | N14: Menyusul | S14: SLTA/SMA | T14: Swasta | U14: O | V14: 6471012808740006 | W14: 6471015812520001 | X14: 082351343230 | Y14: Selfanicc@gmail.com
A15: 14 | B15: 6471051803210005 | C15: Barbara Feny Odjan | D15: Wanita | E15: 33039 | G15: Katolik | K15: Masih Hidup | M15: St.Joseph Tanjung Balai Karimun | N15: III | S15: D3 | T15: Ibu Rumah Tangga | U15: A | V15: 5371025506900011 | W15: 6471051803210005 | X15: 081270098588 | Y15: Barbarafenyodjan@gmail.com
A16: 15 | B16: 6471061006140007 | C16: Barin Pradana | D16: Pria | E16: 41635 | G16: Katolik | K16: Masih Hidup | M16: st klement 1 sepinggan | N16: I | S16: SD | T16: pelajar | U16: A | V16: 6472022712130002 | W16: 6471061006140007 | X16: 081346305051 | Y16: barinpradana@gmail.com
A17: 16 | B17: 6471042602160005 | C17: Casey matthew cozlov maengkom | D17: Pria | E17: 39317 | G17: Katolik | K17: Masih Hidup | M17: Hati kudus yesus tomohon | N17: LB xxii/326 | S17: SLTP/SMP | T17: Smp | U17: O | V17: 6471052308070001 | W17: 6471042602160005 | X17: 082351343230 | Y17: Selfanicc@gmail.com
A18: 17 | B18: 6471050909090037 | C18: Celine Nathalia kusuma | D18: Wanita | E18: 41390 | G18: Katolik | K18: Masih Hidup | M18: St klemens 1 | S18: SD | T18: Siswa | U18: A | V18: 6471066604130001 | W18: 6471050909090037 | X18: Blm ada | Y18: Blm ada
A19: 18 | B19: 6471050909090037 | C19: Christian kusuma | D19: Pria | E19: 26829 | G19: Katolik | K19: Masih Hidup | M19: Gembala yang baik | S19: S1 | T19: Wiraswasta | U19: O | V19: 6471051406730004 | W19: 6471050909090037 | X19: 0811545078 | Y19: Christiankodok@yahoo.com
A20: 19 | B20: 6471042602160005 | C20: Christina selfani runtu | D20: Wanita | E20: 28701 | G20: Katolik | K20: Masih Hidup | M20: Santa theresia | N20: Menyusul | S20: D1 | T20: Irt/swasta | U20: O | V20: 6471057007780002 | W20: 6471042602160005 | X20: 082351343230 | Y20: Selfanicc@gmail.com
A21: 20 | B21: 6471052011090035 | C21: CRISTOPORUS COLOMBUS | D21: Pria | E21: 36679 | G21: Katolik | K21: Masih Hidup | M21: SANTO MIKAEL LABASA | N21: IV-C | S21: SLTA/SMA | T21: Karyawan swasta | U21: B | V21: 6471050206000004 | W21: 6471052011090035 | X21: 081346435198 | Y21: Colombuslombus@gmail.com
A22: 21 | B22: 6471051803210005 | C22: Densius Christian Naga | D22: Pria | E22: 32505 | G22: Katolik | K22: Masih Hidup | M22: St. Yoseph Pekerja Penfui | N22: III | S22: S1 | T22: Pegawai Negeri Sipil | U22: B | V22: 5371032812880002 | W22: 6471051803210005 | X22: 081282411516 | Y22: Christiannaga88@gmail.com
A23: 22 | B23: 6471061006140007 | C23: Diana Dewi Sukawati | D23: Wanita | E23: 28986 | G23: Katolik | K23: Masih Hidup | M23: Gereja SPM Terkandung tanpa noda tarakan | N23: III | S23: S1 | T23: swasta | U23: Tidak tahu | V23: 6472025105790006 | W23: 6471061006140007 | X23: 081346305051 | Y23: Sukawatidiana@gmail.com
A24: 23 | B24: 6471052312200007 | C24: Dina Wulandari | D24: Wanita | E24: 35404 | G24: Katolik | K24: Masih Hidup | M24: Santa Theresia Prapatan | N24: V | S24: S1 | T24: Karyawan Swasta | U24: Tidak tahu | V24: 6471054512960001 | W24: 6471052312200007 | X24: 081254771052 | Y24: dina.wulandari13@gmail.com
A25: 24 | B25: 6471052312200007 | C25: Dina Wulandari | D25: Wanita | E25: 35404 | G25: Katolik | K25: Masih Hidup | M25: Paroki Santa Theresia Prapatan Balikpapan | N25: V | S25: S1 | T25: Karyawan Swasta | U25: Tidak tahu | V25: 6471054512960001 | W25: 6471052312200007 | X25: 081254771052 | Y25: dina.wulandari13@gmail.com
A26: 25 | B26: 6471011009090020 | C26: Elisabeth Mantiri | D26: Wanita | E26: 19346 | G26: Katolik | K26: Masih Hidup | M26: Hati kudus yesus tomohon | N26: Menyusul | S26: D2 | T26: Pensiunan guru | U26: O | V26: 6471015812520001 | W26: 6471011009090020 | X26: 082351343230 | Y26: Selfanicc@gmail.com
A27: 26 | B27: 6471010309190009 | C27: Emanuel Juniarto Mere | D27: Wanita | E27: 42181 | G27: Katolik | K27: Masih Hidup | M27: Yesus Kerahiman Ilahi Aeramo | N27: IVCMXXXI | S27: KB/TK | U27: Tidak tahu | V27: 5316062606150001 | W27: 6471010309190009
A28: 27 | B28: 6402060105090019 | C28: EMELINDA FRANSISKA | D28: Wanita | E28: 34773 | G28: Katolik | K28: Masih Hidup | M28: ST. MARTINUS BONE - BONE | N28: 1086/REG I | S28: S1 | T28: BELUM BEKERJA | U28: Tidak tahu | V28: 7322025503950002 | W28: 6402060105090019 | X28: 085342634570 | Y28: Ajusecery@yahoo.com
A29: 28 | B29: 6471052409090031 | C29: Endang Winarti Ningsih | D29: Wanita | E29: 22884 | G29: Katolik | K29: Masih Hidup | M29: Paroki Santa Theresia Prapatan Balikpapan | N29: III | S29: SD | T29: Ibu Rumah Tangga | U29: O | V29: 6471056608620002 | W29: 6471052409090031 | X29: 085347992266
A30: 29 | B30: 6471051210090014 | C30: Endang Yudhaningsih | D30: Wanita | E30: 18628 | G30: Katolik | K30: Masih Hidup | M30: St. Theresia Balikpapan | S30: SLTA/SMA | T30: Ibu Rumah Tangga | U30: O | V30: 6471057112500064 | W30: 6471051210090014 | X30: 085716012223 | Y30: -
A31: 30 | B31: 6471052009120021 | C31: Ernis Pindan Widyawati | D31: Wanita | E31: 28849 | G31: Katolik | K31: Masih Hidup | M31: Klemens 1 | N31: I | S31: S1 | T31: Ibu Rumah Tangga | U31: B | V31: 6471056612780013 | W31: 6471052009120021 | X31: +6281258002516
A32: 31 | B32: 6471052806160018 | C32: Febrianty Anastasia Malau | D32: Wanita | E32: 36946 | G32: Katolik | K32: Masih Hidup | M32: Santo Petrus | N32: IV | S32: SLTA/SMA | U32: O | V32: 6471016402010004 | W32: 6471052806160018 | X32: 082122242908 | Y32: agnesmonica2170@gmail.com
A33: 32 | B33: 6471052709120093 | C33: Fenesia Friska Sinurat, S.Pd | D33: Wanita | E33: 28165 | G33: Katolik | K33: Masih Hidup | M33: Paroki St Mikael Pangururan | N33: XIV | S33: S1 | T33: PNS (Guru) | U33: O | V33: 6471054902770004 | W33: 6471052709120093 | X33: 08126328520 | Y33: fenesiasiska@gmail.com
A34: 33 | B34: 6471052709120093 | C34: Fenesia Friska Sinurat, S.Pd | D34: Wanita | E34: 28165 | G34: Katolik | K34: Masih Hidup | M34: St.Mikael Pangururan | N34: XIV | S34: S1 | T34: PNS/Guru | U34: O | V34: 64711054902770004 | W34: 6471052709120093 | X34: 08126328520 | Y34: fenesiasiska@gmail.com
A35: 34 | B35: 6471051803090046 | C35: fransisca gisella ayu rahmadhani | D35: Wanita | E35: 38444 | G35: Katolik | K35: Masih Hidup | M35: yohanes rasul wonogiri | S35: SLTA/SMA | T35: pelajar | U35: AB | V35: 6471054204050004 | W35: 6471051803090046 | X35: +62 877-4934-6290
A36: 35 | B36: 6471050901140019 | C36: GABRIEL NAIARA ADISTIA GANTARI | D36: Wanita | E36: 41373 | G36: Katolik | K36: Masih Hidup | M36: SANTO KLEMENS I BALIKPAPAN | N36: I | S36: KB/TK | U36: A | V36: 6471054904130005 | W36: 6471050901140019
A37: 36 | B37: 6471052409090031 | C37: Hadi Sujono | D37: Pria | E37: 19287 | G37: Katolik | K37: Masih Hidup | M37: Paroki Santa Theresia Prapatan Balikpapan | N37: III | S37: SLTP/SMP | T37: Buruh Harian Lepas | U37: AB | V37: 6471052010520002 | W37: 6471052409090031 | X37: 085347992266
A38: 37 | B38: 6471051210090021 | C38: HARIYOTEJO DWINANTO | D38: Pria | E38: 27396 | G38: Katolik | K38: Masih Hidup | M38: KEPANJEN | N38: II | S38: SLTA/SMA | T38: WIRASWASTA | U38: O | V38: 6471050201750011 | W38: 6471051210090021 | X38: 081316900510 | Y38: Hdwinanto.mwc@gmail.com
A39: 38 | B39: 6471051210090021 | C39: Hastari Kusumawardhani | D39: Wanita | E39: 28761 | G39: Katolik | K39: Masih Hidup | M39: St. Maria Tak Bernoda Kepanjen | N39: II | S39: S1 | T39: Wiraswasta | U39: O | V39: 6471056809780005 | W39: 6471051210090021 | X39: 081548607099 | Y39: dhwidodo@yahoo.com
A40: 39 | B40: 6471050102190004 | C40: Hipolitus kanisius bogar | D40: Pria | E40: 18 | G40: Katolik | K40: Masih Hidup | M40: Paroki Santo Michael Nita | S40: SLTP/SMP | T40: Driver | U40: O | V40: 5301241907830001 | W40: 6471050102190004 | X40: 081351595667 | Y40: Chievocaprio99@gmail.com
...

Sheet BAPTIS
A1: ID Umat | B1: Nama | C1: Lingkungan | D1: Jenis Kelamin | E1: Tanggal Lahir | F1: Tanggal Baptis | G1: Umur Saat Baptis | H1: Keterangan

Sheet DITERIMA MASUK
A1: ID Umat | B1: Nama | C1: Lingkungan | D1: Tanggal Masuk | E1: Asal Gereja Kristen | F1: Tanpa Baptis | G1: Keterangan

Sheet MUTASI
A1: ID Umat | B1: Nama | C1: Lingkungan | D1: Jenis Mutasi | E1: Tanggal Mutasi | F1: Rute | G1: Asal/Tujuan | H1: Paroki/Keuskupan | I1: Keterangan
D2: Keluar | F2: Keuskupan lain

Sheet PINDAH AGAMA
A1: ID Umat | B1: Nama | C1: Lingkungan | D1: Tanggal Pindah Agama | E1: Agama Baru | F1: Keterangan

Sheet KOMUNI PERTAMA
A1: ID Umat | B1: Nama | C1: Lingkungan | D1: Jenis Kelamin | E1: Tanggal Komuni I | F1: Paroki/Gereja | G1: Keterangan

Sheet PERKAWINAN GEREJANI
A1: ID KK | B1: Nama Pasangan | C1: Lingkungan | D1: Tanggal Perkawinan | E1: Agama Pasangan | F1: Keterangan

Sheet PEMBUBARAN
A1: ID KK | B1: Nama Pasangan | C1: Lingkungan | D1: Tanggal Pembubaran | E1: Pelaksanaan Lewat | F1: Keterangan

Sheet PERMINYAKAN SUCI
A1: ID Umat | B1: Nama | C1: Lingkungan | D1: Jenis Kelamin | E1: Tanggal Sakramen | F1: Keterangan

Sheet KEMATIAN
A1: ID Umat | B1: Nama | C1: Lingkungan | D1: Jenis Kelamin | E1: Tanggal Lahir | F1: Tanggal Meninggal | G1: Umur Saat Meninggal | H1: Keterangan
G2: =IF(OR(E2="",F2=""),"",DATEDIF(E2,F2,"Y"))
G3: =IF(OR(E3="",F3=""),"",DATEDIF(E3,F3,"Y"))
G4: =IF(OR(E4="",F4=""),"",DATEDIF(E4,F4,"Y"))
G5: =IF(OR(E5="",F5=""),"",DATEDIF(E5,F5,"Y"))
G6: =IF(OR(E6="",F6=""),"",DATEDIF(E6,F6,"Y"))
G7: =IF(OR(E7="",F7=""),"",DATEDIF(E7,F7,"Y"))
G8: =IF(OR(E8="",F8=""),"",DATEDIF(E8,F8,"Y"))
G9: =IF(OR(E9="",F9=""),"",DATEDIF(E9,F9,"Y"))
G10: =IF(OR(E10="",F10=""),"",DATEDIF(E10,F10,"Y"))
G11: =IF(OR(E11="",F11=""),"",DATEDIF(E11,F11,"Y"))
G12: =IF(OR(E12="",F12=""),"",DATEDIF(E12,F12,"Y"))
G13: =IF(OR(E13="",F13=""),"",DATEDIF(E13,F13,"Y"))
... G1001: =IF(OR(E1001="",F1001=""),"",DATEDIF(E1001,F1001,"Y"))

Sheet SEMINARI BIARA
A1: ID Umat | B1: Nama | C1: Lingkungan | D1: Jenis Kelamin | E1: Jalur Seminari/Biara | F1: Status | G1: Tanggal Mulai/Status | H1: Keterangan

Sheet REKAP LINGKUNGAN
A1: REKAP STATISTIK LINGKUNGAN — PAROKI ST. KLEMENT I SEPINGGAN BALIKPAPAN 2026
A2: Ketik nama lingkungan di kolom A. Kolom angka terhitung otomatis dari database.
A3: *Kolom 1.1/1.2 mengikuti kategori pada formulir sumber: mutasi antar-paroki dalam keuskupan vs keuskupan lain.
A4: Nama Lingkungan | B4: KK | C4: Jiwa | D4: Baptis 2026 | E4: Diterima dari Kristen Lain | F4: Pindah Masuk dari Paroki Lain | G4: Pindah Masuk dari Keuskupan Lain | H4: Meninggal | I4: Pindah Keluar ke Paroki Lain | J4: Pindah Keluar ke Keuskupan Lain | K4: Pindah Agama | L4: Saldo Perubahan | M4: Komuni I | N4: Perkawinan Gerejani | O4: Pembubaran | P4: Perminyakan Suci | Q4: Kematian | R4: Mulai Seminari/Biara | S4: Sedang Belajar Seminari
B5: =IF($A5="","",COUNTIF('DATA KK'!$E$2:$E$501,$A5)) | C5: =IF($A5="","",COUNTIF('DATA UMAT'!$H$2:$H$2001,$A5)) | D5: =IF($A5="","",COUNTIFS(BAPTIS!$C$2:$C$1001,$A5,BAPTIS!$F$2:$F$1001,">="&DATE(2026,1,1),BAPTIS!$F$2:$F$1001,"<="&DATE(2026,12,31))) | E5: =IF($A5="","",COUNTIFS('DITERIMA MASUK'!$C$2:$C$1001,$A5,'DITERIMA MASUK'!$D$2:$D$1001,">="&DATE(2026,1,1),'DITERIMA MASUK'!$D$2:$D$1001,"<="&DATE(2026,12,31))) | F5: =IF($A5="","",COUNTIFS(MUTASI!$C$2:$C$1001,$A5,MUTASI!$D$2:$D$1001,"Masuk",MUTASI!$F$2:$F$1001,"Paroki lain dalam keuskupan",MUTASI!$E$2:$E$1001,">="&DATE(2026,1,1),MUTASI!$E$2:$E$1001,"<="&DATE(2026,12,31))) | G5: =IF($A5="","",COUNTIFS(MUTASI!$C$2:$C$1001,$A5,MUTASI!$D$2:$D$1001,"Masuk",MUTASI!$F$2:$F$1001,"Keuskupan lain",MUTASI!$E$2:$E$1001,">="&DATE(2026,1,1),MUTASI!$E$2:$E$1001,"<="&DATE(2026,12,31))) | H5: =IF($A5="","",COUNTIFS(KEMATIAN!$C$2:$C$1001,$A5,KEMATIAN!$F$2:$F$1001,">="&DATE(2026,1,1),KEMATIAN!$F$2:$F$1001,"<="&DATE(2026,12,31))) | I5: =IF($A5="","",COUNTIFS(MUTASI!$C$2:$C$1001,$A5,MUTASI!$D$2:$D$1001,"Keluar",MUTASI!$F$2:$F$1001,"Paroki lain dalam keuskupan",MUTASI!$E$2:$E$1001,">="&DATE(2026,1,1),MUTASI!$E$2:$E$1001,"<="&DATE(2026,12,31))) | J5: =IF($A5="","",COUNTIFS(MUTASI!$C$2:$C$1001,$A5,MUTASI!$D$2:$D$1001,"Keluar",MUTASI!$F$2:$F$1001,"Keuskupan lain",MUTASI!$E$2:$E$1001,">="&DATE(2026,1,1),MUTASI!$E$2:$E$1001,"<="&DATE(2026,12,31))) | K5: =IF($A5="","",COUNTIFS('PINDAH AGAMA'!$C$2:$C$1001,$A5,'PINDAH AGAMA'!$D$2:$D$1001,">="&DATE(2026,1,1),'PINDAH AGAMA'!$D$2:$D$1001,"<="&DATE(2026,12,31))) | L5: =IF($A5="","",D5+E5+F5+G5-H5-I5-J5-K5) | M5: =IF($A5="","",COUNTIFS('KOMUNI PERTAMA'!$C$2:$C$1001,$A5,'KOMUNI PERTAMA'!$E$2:$E$1001,">="&DATE(2026,1,1),'KOMUNI PERTAMA'!$E$2:$E$1001,"<="&DATE(2026,12,31))) | N5: =IF($A5="","",COUNTIFS('PERKAWINAN GEREJANI'!$C$2:$C$1001,$A5,'PERKAWINAN GEREJANI'!$D$2:$D$1001,">="&DATE(2026,1,1),'PERKAWINAN GEREJANI'!$D$2:$D$1001,"<="&DATE(2026,12,31))) | O5: =IF($A5="","",COUNTIFS(PEMBUBARAN!$C$2:$C$1001,$A5,PEMBUBARAN!$D$2:$D$1001,">="&DATE(2026,1,1),PEMBUBARAN!$D$2:$D$1001,"<="&DATE(2026,12,31))) | P5: =IF($A5="","",COUNTIFS('PERMINYAKAN SUCI'!$C$2:$C$1001,$A5,'PERMINYAKAN SUCI'!$E$2:$E$1001,">="&DATE(2026,1,1),'PERMINYAKAN SUCI'!$E$2:$E$1001,"<="&DATE(2026,12,31))) | Q5: =IF($A5="","",H5) | R5: =IF($A5="","",COUNTIFS('SEMINARI BIARA'!$C$2:$C$1001,$A5,'SEMINARI BIARA'!$F$2:$F$1001,"Mulai masuk 2026",'SEMINARI BIARA'!$G$2:$G$1001,">="&DATE(2026,1,1),'SEMINARI BIARA'!$G$2:$G$1001,"<="&DATE(2026,12,31))) | S5: =IF($A5="","",COUNTIFS('SEMINARI BIARA'!$C$2:$C$1001,$A5,'SEMINARI BIARA'!$F$2:$F$1001,"Sedang belajar 2026"))
B6: =IF($A6="","",COUNTIF('DATA KK'!$E$2:$E$501,$A6)) | C6: =IF($A6="","",COUNTIF('DATA UMAT'!$H$2:$H$2001,$A6)) | D6: =IF($A6="","",COUNTIFS(BAPTIS!$C$2:$C$1001,$A6,BAPTIS!$F$2:$F$1001,">="&DATE(2026,1,1),BAPTIS!$F$2:$F$1001,"<="&DATE(2026,12,31))) | E6: =IF($A6="","",COUNTIFS('DITERIMA MASUK'!$C$2:$C$1001,$A6,'DITERIMA MASUK'!$D$2:$D$1001,">="&DATE(2026,1,1),'DITERIMA MASUK'!$D$2:$D$1001,"<="&DATE(2026,12,31))) | F6: =IF($A6="","",COUNTIFS(MUTASI!$C$2:$C$1001,$A6,MUTASI!$D$2:$D$1001,"Masuk",MUTASI!$F$2:$F$1001,"Paroki lain dalam keuskupan",MUTASI!$E$2:$E$1001,">="&DATE(2026,1,1),MUTASI!$E$2:$E$1001,"<="&DATE(2026,12,31))) | G6: =IF($A6="","",COUNTIFS(MUTASI!$C$2:$C$1001,$A6,MUTASI!$D$2:$D$1001,"Masuk",MUTASI!$F$2:$F$1001,"Keuskupan lain",MUTASI!$E$2:$E$1001,">="&DATE(2026,1,1),MUTASI!$E$2:$E$1001,"<="&DATE(2026,12,31))) | H6: =IF($A6="","",COUNTIFS(KEMATIAN!$C$2:$C$1001,$A6,KEMATIAN!$F$2:$F$1001,">="&DATE(2026,1,1),KEMATIAN!$F$2:$F$1001,"<="&DATE(2026,12,31))) | I6: =IF($A6="","",COUNTIFS(MUTASI!$C$2:$C$1001,$A6,MUTASI!$D$2:$D$1001,"Keluar",MUTASI!$F$2:$F$1001,"Paroki lain dalam keuskupan",MUTASI!$E$2:$E$1001,">="&DATE(2026,1,1),MUTASI!$E$2:$E$1001,"<="&DATE(2026,12,31))) | J6: =IF($A6="","",COUNTIFS(MUTASI!$C$2:$C$1001,$A6,MUTASI!$D$2:$D$1001,"Keluar",MUTASI!$F$2:$F$1001,"Keuskupan lain",MUTASI!$E$2:$E$1001,">="&DATE(2026,1,1),MUTASI!$E$2:$E$1001,"<="&DATE(2026,12,31))) | K6: =IF($A6="","",COUNTIFS('PINDAH AGAMA'!$C$2:$C$1001,$A6,'PINDAH AGAMA'!$D$2:$D$1001,">="&DATE(2026,1,1),'PINDAH AGAMA'!$D$2:$D$1001,"<="&DATE(2026,12,31))) | L6: =IF($A6="","",D6+E6+F6+G6-H6-I6-J6-K6) | M6: =IF($A6="","",COUNTIFS('KOMUNI PERTAMA'!$C$2:$C$1001,$A6,'KOMUNI PERTAMA'!$E$2:$E$1001,">="&DATE(2026,1,1),'KOMUNI PERTAMA'!$E$2:$E$1001,"<="&DATE(2026,12,31))) | N6: =IF($A6="","",COUNTIFS('PERKAWINAN GEREJANI'!$C$2:$C$1001,$A6,'PERKAWINAN GEREJANI'!$D$2:$D$1001,">="&DATE(2026,1,1),'PERKAWINAN GEREJANI'!$D$2:$D$1001,"<="&DATE(2026,12,31))) | O6: =IF($A6="","",COUNTIFS(PEMBUBARAN!$C$2:$C$1001,$A6,PEMBUBARAN!$D$2:$D$1001,">="&DATE(2026,1,1),PEMBUBARAN!$D$2:$D$1001,"<="&DATE(2026,12,31))) | P6: =IF($A6="","",COUNTIFS('PERMINYAKAN SUCI'!$C$2:$C$1001,$A6,'PERMINYAKAN SUCI'!$E$2:$E$1001,">="&DATE(2026,1,1),'PERMINYAKAN SUCI'!$E$2:$E$1001,"<="&DATE(2026,12,31))) | Q6: =IF($A6="","",H6) | R6: =IF($A6="","",COUNTIFS('SEMINARI BIARA'!$C$2:$C$1001,$A6,'SEMINARI BIARA'!$F$2:$F$1001,"Mulai masuk 2026",'SEMINARI BIARA'!$G$2:$G$1001,">="&DATE(2026,1,1),'SEMINARI BIARA'!$G$2:$G$1001,"<="&DATE(2026,12,31))) | S6: =IF($A6="","",COUNTIFS('SEMINARI BIARA'!$C$2:$C$1001,$A6,'SEMINARI BIARA'!$F$2:$F$1001,"Sedang belajar 2026"))
B7: =IF($A7="","",COUNTIF('DATA KK'!$E$2:$E$501,$A7)) | C7: =IF($A7="","",COUNTIF('DATA UMAT'!$H$2:$H$2001,$A7)) | D7: =IF($A7="","",COUNTIFS(BAPTIS!$C$2:$C$1001,$A7,BAPTIS!$F$2:$F$1001,">="&DATE(2026,1,1),BAPTIS!$F$2:$F$1001,"<="&DATE(2026,12,31))) | E7: =IF($A7="","",COUNTIFS('DITERIMA MASUK'!$C$2:$C$1001,$A7,'DITERIMA MASUK'!$D$2:$D$1001,">="&DATE(2026,1,1),'DITERIMA MASUK'!$D$2:$D$1001,"<="&DATE(2026,12,31))) | F7: =IF($A7="","",COUNTIFS(MUTASI!$C$2:$C$1001,$A7,MUTASI!$D$2:$D$1001,"Masuk",MUTASI!$F$2:$F$1001,"Paroki lain dalam keuskupan",MUTASI!$E$2:$E$1001,">="&DATE(2026,1,1),MUTASI!$E$2:$E$1001,"<="&DATE(2026,12,31))) | G7: =IF($A7="","",COUNTIFS(MUTASI!$C$2:$C$1001,$A7,MUTASI!$D$2:$D$1001,"Masuk",MUTASI!$F$2:$F$1001,"Keuskupan lain",MUTASI!$E$2:$E$1001,">="&DATE(2026,1,1),MUTASI!$E$2:$E$1001,"<="&DATE(2026,12,31))) | H7: =IF($A7="","",COUNTIFS(KEMATIAN!$C$2:$C$1001,$A7,KEMATIAN!$F$2:$F$1001,">="&DATE(2026,1,1),KEMATIAN!$F$2:$F$1001,"<="&DATE(2026,12,31))) | I7: =IF($A7="","",COUNTIFS(MUTASI!$C$2:$C$1001,$A7,MUTASI!$D$2:$D$1001,"Keluar",MUTASI!$F$2:$F$1001,"Paroki lain dalam keuskupan",MUTASI!$E$2:$E$1001,">="&DATE(2026,1,1),MUTASI!$E$2:$E$1001,"<="&DATE(2026,12,31))) | J7: =IF($A7="","",COUNTIFS(MUTASI!$C$2:$C$1001,$A7,MUTASI!$D$2:$D$1001,"Keluar",MUTASI!$F$2:$F$1001,"Keuskupan lain",MUTASI!$E$2:$E$1001,">="&DATE(2026,1,1),MUTASI!$E$2:$E$1001,"<="&DATE(2026,12,31))) | K7: =IF($A7="","",COUNTIFS('PINDAH AGAMA'!$C$2:$C$1001,$A7,'PINDAH AGAMA'!$D$2:$D$1001,">="&DATE(2026,1,1),'PINDAH AGAMA'!$D$2:$D$1001,"<="&DATE(2026,12,31))) | L7: =IF($A7="","",D7+E7+F7+G7-H7-I7-J7-K7) | M7: =IF($A7="","",COUNTIFS('KOMUNI PERTAMA'!$C$2:$C$1001,$A7,'KOMUNI PERTAMA'!$E$2:$E$1001,">="&DATE(2026,1,1),'KOMUNI PERTAMA'!$E$2:$E$1001,"<="&DATE(2026,12,31))) | N7: =IF($A7="","",COUNTIFS('PERKAWINAN GEREJANI'!$C$2:$C$1001,$A7,'PERKAWINAN GEREJANI'!$D$2:$D$1001,">="&DATE(2026,1,1),'PERKAWINAN GEREJANI'!$D$2:$D$1001,"<="&DATE(2026,12,31))) | O7: =IF($A7="","",COUNTIFS(PEMBUBARAN!$C$2:$C$1001,$A7,PEMBUBARAN!$D$2:$D$1001,">="&DATE(2026,1,1),PEMBUBARAN!$D$2:$D$1001,"<="&DATE(2026,12,31))) | P7: =IF($A7="","",COUNTIFS('PERMINYAKAN SUCI'!$C$2:$C$1001,$A7,'PERMINYAKAN SUCI'!$E$2:$E$1001,">="&DATE(2026,1,1),'PERMINYAKAN SUCI'!$E$2:$E$1001,"<="&DATE(2026,12,31))) | Q7: =IF($A7="","",H7) | R7: =IF($A7="","",COUNTIFS('SEMINARI BIARA'!$C$2:$C$1001,$A7,'SEMINARI BIARA'!$F$2:$F$1001,"Mulai masuk 2026",'SEMINARI BIARA'!$G$2:$G$1001,">="&DATE(2026,1,1),'SEMINARI BIARA'!$G$2:$G$1001,"<="&DATE(2026,12,31))) | S7: =IF($A7="","",COUNTIFS('SEMINARI BIARA'!$C$2:$C$1001,$A7,'SEMINARI BIARA'!$F$2:$F$1001,"Sedang belajar 2026"))
B8: =IF($A8="","",COUNTIF('DATA KK'!$E$2:$E$501,$A8)) | C8: =IF($A8="","",COUNTIF('DATA UMAT'!$H$2:$H$2001,$A8)) | D8: =IF($A8="","",COUNTIFS(BAPTIS!$C$2:$C$1001,$A8,BAPTIS!$F$2:$F$1001,">="&DATE(2026,1,1),BAPTIS!$F$2:$F$1001,"<="&DATE(2026,12,31))) | E8: =IF($A8="","",COUNTIFS('DITERIMA MASUK'!$C$2:$C$1001,$A8,'DITERIMA MASUK'!$D$2:$D$1001,">="&DATE(2026,1,1),'DITERIMA MASUK'!$D$2:$D$1001,"<="&DATE(2026,12,31))) | F8: =IF($A8="","",COUNTIFS(MUTASI!$C$2:$C$1001,$A8,MUTASI!$D$2:$D$1001,"Masuk",MUTASI!$F$2:$F$1001,"Paroki lain dalam keuskupan",MUTASI!$E$2:$E$1001,">="&DATE(2026,1,1),MUTASI!$E$2:$E$1001,"<="&DATE(2026,12,31))) | G8: =IF($A8="","",COUNTIFS(MUTASI!$C$2:$C$1001,$A8,MUTASI!$D$2:$D$1001,"Masuk",MUTASI!$F$2:$F$1001,"Keuskupan lain",MUTASI!$E$2:$E$1001,">="&DATE(2026,1,1),MUTASI!$E$2:$E$1001,"<="&DATE(2026,12,31))) | H8: =IF($A8="","",COUNTIFS(KEMATIAN!$C$2:$C$1001,$A8,KEMATIAN!$F$2:$F$1001,">="&DATE(2026,1,1),KEMATIAN!$F$2:$F$1001,"<="&DATE(2026,12,31))) | I8: =IF($A8="","",COUNTIFS(MUTASI!$C$2:$C$1001,$A8,MUTASI!$D$2:$D$1001,"Keluar",MUTASI!$F$2:$F$1001,"Paroki lain dalam keuskupan",MUTASI!$E$2:$E$1001,">="&DATE(2026,1,1),MUTASI!$E$2:$E$1001,"<="&DATE(2026,12,31))) | J8: =IF($A8="","",COUNTIFS(MUTASI!$C$2:$C$1001,$A8,MUTASI!$D$2:$D$1001,"Keluar",MUTASI!$F$2:$F$1001,"Keuskupan lain",MUTASI!$E$2:$E$1001,">="&DATE(2026,1,1),MUTASI!$E$2:$E$1001,"<="&DATE(2026,12,31))) | K8: =IF($A8="","",COUNTIFS('PINDAH AGAMA'!$C$2:$C$1001,$A8,'PINDAH AGAMA'!$D$2:$D$1001,">="&DATE(2026,1,1),'PINDAH AGAMA'!$D$2:$D$1001,"<="&DATE(2026,12,31))) | L8: =IF($A8="","",D8+E8+F8+G8-H8-I8-J8-K8) | M8: =IF($A8="","",COUNTIFS('KOMUNI PERTAMA'!$C$2:$C$1001,$A8,'KOMUNI PERTAMA'!$E$2:$E$1001,">="&DATE(2026,1,1),'KOMUNI PERTAMA'!$E$2:$E$1001,"<="&DATE(2026,12,31))) | N8: =IF($A8="","",COUNTIFS('PERKAWINAN GEREJANI'!$C$2:$C$1001,$A8,'PERKAWINAN GEREJANI'!$D$2:$D$1001,">="&DATE(2026,1,1),'PERKAWINAN GEREJANI'!$D$2:$D$1001,"<="&DATE(2026,12,31))) | O8: =IF($A8="","",COUNTIFS(PEMBUBARAN!$C$2:$C$1001,$A8,PEMBUBARAN!$D$2:$D$1001,">="&DATE(2026,1,1),PEMBUBARAN!$D$2:$D$1001,"<="&DATE(2026,12,31))) | P8: =IF($A8="","",COUNTIFS('PERMINYAKAN SUCI'!$C$2:$C$1001,$A8,'PERMINYAKAN SUCI'!$E$2:$E$1001,">="&DATE(2026,1,1),'PERMINYAKAN SUCI'!$E$2:$E$1001,"<="&DATE(2026,12,31))) | Q8: =IF($A8="","",H8) | R8: =IF($A8="","",COUNTIFS('SEMINARI BIARA'!$C$2:$C$1001,$A8,'SEMINARI BIARA'!$F$2:$F$1001,"Mulai masuk 2026",'SEMINARI BIARA'!$G$2:$G$1001,">="&DATE(2026,1,1),'SEMINARI BIARA'!$G$2:$G$1001,"<="&DATE(2026,12,31))) | S8: =IF($A8="","",COUNTIFS('SEMINARI BIARA'!$C$2:$C$1001,$A8,'SEMINARI BIARA'!$F$2:$F$1001,"Sedang belajar 2026"))
B9: =IF($A9="","",COUNTIF('DATA KK'!$E$2:$E$501,$A9)) | C9: =IF($A9="","",COUNTIF('DATA UMAT'!$H$2:$H$2001,$A9)) | D9: =IF($A9="","",COUNTIFS(BAPTIS!$C$2:$C$1001,$A9,BAPTIS!$F$2:$F$1001,">="&DATE(2026,1,1),BAPTIS!$F$2:$F$1001,"<="&DATE(2026,12,31))) | E9: =IF($A9="","",COUNTIFS('DITERIMA MASUK'!$C$2:$C$1001,$A9,'DITERIMA MASUK'!$D$2:$D$1001,">="&DATE(2026,1,1),'DITERIMA MASUK'!$D$2:$D$1001,"<="&DATE(2026,12,31))) | F9: =IF($A9="","",COUNTIFS(MUTASI!$C$2:$C$1001,$A9,MUTASI!$D$2:$D$1001,"Masuk",MUTASI!$F$2:$F$1001,"Paroki lain dalam keuskupan",MUTASI!$E$2:$E$1001,">="&DATE(2026,1,1),MUTASI!$E$2:$E$1001,"<="&DATE(2026,12,31))) | G9: =IF($A9="","",COUNTIFS(MUTASI!$C$2:$C$1001,$A9,MUTASI!$D$2:$D$1001,"Masuk",MUTASI!$F$2:$F$1001,"Keuskupan lain",MUTASI!$E$2:$E$1001,">="&DATE(2026,1,1),MUTASI!$E$2:$E$1001,"<="&DATE(2026,12,31))) | H9: =IF($A9="","",COUNTIFS(KEMATIAN!$C$2:$C$1001,$A9,KEMATIAN!$F$2:$F$1001,">="&DATE(2026,1,1),KEMATIAN!$F$2:$F$1001,"<="&DATE(2026,12,31))) | I9: =IF($A9="","",COUNTIFS(MUTASI!$C$2:$C$1001,$A9,MUTASI!$D$2:$D$1001,"Keluar",MUTASI!$F$2:$F$1001,"Paroki lain dalam keuskupan",MUTASI!$E$2:$E$1001,">="&DATE(2026,1,1),MUTASI!$E$2:$E$1001,"<="&DATE(2026,12,31))) | J9: =IF($A9="","",COUNTIFS(MUTASI!$C$2:$C$1001,$A9,MUTASI!$D$2:$D$1001,"Keluar",MUTASI!$F$2:$F$1001,"Keuskupan lain",MUTASI!$E$2:$E$1001,">="&DATE(2026,1,1),MUTASI!$E$2:$E$1001,"<="&DATE(2026,12,31))) | K9: =IF($A9="","",COUNTIFS('PINDAH AGAMA'!$C$2:$C$1001,$A9,'PINDAH AGAMA'!$D$2:$D$1001,">="&DATE(2026,1,1),'PINDAH AGAMA'!$D$2:$D$1001,"<="&DATE(2026,12,31))) | L9: =IF($A9="","",D9+E9+F9+G9-H9-I9-J9-K9) | M9: =IF($A9="","",COUNTIFS('KOMUNI PERTAMA'!$C$2:$C$1001,$A9,'KOMUNI PERTAMA'!$E$2:$E$1001,">="&DATE(2026,1,1),'KOMUNI PERTAMA'!$E$2:$E$1001,"<="&DATE(2026,12,31))) | N9: =IF($A9="","",COUNTIFS('PERKAWINAN GEREJANI'!$C$2:$C$1001,$A9,'PERKAWINAN GEREJANI'!$D$2:$D$1001,">="&DATE(2026,1,1),'PERKAWINAN GEREJANI'!$D$2:$D$1001,"<="&DATE(2026,12,31))) | O9: =IF($A9="","",COUNTIFS(PEMBUBARAN!$C$2:$C$1001,$A9,PEMBUBARAN!$D$2:$D$1001,">="&DATE(2026,1,1),PEMBUBARAN!$D$2:$D$1001,"<="&DATE(2026,12,31))) | P9: =IF($A9="","",COUNTIFS('PERMINYAKAN SUCI'!$C$2:$C$1001,$A9,'PERMINYAKAN SUCI'!$E$2:$E$1001,">="&DATE(2026,1,1),'PERMINYAKAN SUCI'!$E$2:$E$1001,"<="&DATE(2026,12,31))) | Q9: =IF($A9="","",H9) | R9: =IF($A9="","",COUNTIFS('SEMINARI BIARA'!$C$2:$C$1001,$A9,'SEMINARI BIARA'!$F$2:$F$1001,"Mulai masuk 2026",'SEMINARI BIARA'!$G$2:$G$1001,">="&DATE(2026,1,1),'SEMINARI BIARA'!$G$2:$G$1001,"<="&DATE(2026,12,31))) | S9: =IF($A9="","",COUNTIFS('SEMINARI BIARA'!$C$2:$C$1001,$A9,'SEMINARI BIARA'!$F$2:$F$1001,"Sedang belajar 2026"))
B10: =IF($A10="","",COUNTIF('DATA KK'!$E$2:$E$501,$A10)) | C10: =IF($A10="","",COUNTIF('DATA UMAT'!$H$2:$H$2001,$A10)) | D10: =IF($A10="","",COUNTIFS(BAPTIS!$C$2:$C$1001,$A10,BAPTIS!$F$2:$F$1001,">="&DATE(2026,1,1),BAPTIS!$F$2:$F$1001,"<="&DATE(2026,12,31))) | E10: =IF($A10="","",COUNTIFS('DITERIMA MASUK'!$C$2:$C$1001,$A10,'DITERIMA MASUK'!$D$2:$D$1001,">="&DATE(2026,1,1),'DITERIMA MASUK'!$D$2:$D$1001,"<="&DATE(2026,12,31))) | F10: =IF($A10="","",COUNTIFS(MUTASI!$C$2:$C$1001,$A10,MUTASI!$D$2:$D$1001,"Masuk",MUTASI!$F$2:$F$1001,"Paroki lain dalam keuskupan",MUTASI!$E$2:$E$1001,">="&DATE(2026,1,1),MUTASI!$E$2:$E$1001,"<="&DATE(2026,12,31))) | G10: =IF($A10="","",COUNTIFS(MUTASI!$C$2:$C$1001,$A10,MUTASI!$D$2:$D$1001,"Masuk",MUTASI!$F$2:$F$1001,"Keuskupan lain",MUTASI!$E$2:$E$1001,">="&DATE(2026,1,1),MUTASI!$E$2:$E$1001,"<="&DATE(2026,12,31))) | H10: =IF($A10="","",COUNTIFS(KEMATIAN!$C$2:$C$1001,$A10,KEMATIAN!$F$2:$F$1001,">="&DATE(2026,1,1),KEMATIAN!$F$2:$F$1001,"<="&DATE(2026,12,31))) | I10: =IF($A10="","",COUNTIFS(MUTASI!$C$2:$C$1001,$A10,MUTASI!$D$2:$D$1001,"Keluar",MUTASI!$F$2:$F$1001,"Paroki lain dalam keuskupan",MUTASI!$E$2:$E$1001,">="&DATE(2026,1,1),MUTASI!$E$2:$E$1001,"<="&DATE(2026,12,31))) | J10: =IF($A10="","",COUNTIFS(MUTASI!$C$2:$C$1001,$A10,MUTASI!$D$2:$D$1001,"Keluar",MUTASI!$F$2:$F$1001,"Keuskupan lain",MUTASI!$E$2:$E$1001,">="&DATE(2026,1,1),MUTASI!$E$2:$E$1001,"<="&DATE(2026,12,31))) | K10: =IF($A10="","",COUNTIFS('PINDAH AGAMA'!$C$2:$C$1001,$A10,'PINDAH AGAMA'!$D$2:$D$1001,">="&DATE(2026,1,1),'PINDAH AGAMA'!$D$2:$D$1001,"<="&DATE(2026,12,31))) | L10: =IF($A10="","",D10+E10+F10+G10-H10-I10-J10-K10) | M10: =IF($A10="","",COUNTIFS('KOMUNI PERTAMA'!$C$2:$C$1001,$A10,'KOMUNI PERTAMA'!$E$2:$E$1001,">="&DATE(2026,1,1),'KOMUNI PERTAMA'!$E$2:$E$1001,"<="&DATE(2026,12,31))) | N10: =IF($A10="","",COUNTIFS('PERKAWINAN GEREJANI'!$C$2:$C$1001,$A10,'PERKAWINAN GEREJANI'!$D$2:$D$1001,">="&DATE(2026,1,1),'PERKAWINAN GEREJANI'!$D$2:$D$1001,"<="&DATE(2026,12,31))) | O10: =IF($A10="","",COUNTIFS(PEMBUBARAN!$C$2:$C$1001,$A10,PEMBUBARAN!$D$2:$D$1001,">="&DATE(2026,1,1),PEMBUBARAN!$D$2:$D$1001,"<="&DATE(2026,12,31))) | P10: =IF($A10="","",COUNTIFS('PERMINYAKAN SUCI'!$C$2:$C$1001,$A10,'PERMINYAKAN SUCI'!$E$2:$E$1001,">="&DATE(2026,1,1),'PERMINYAKAN SUCI'!$E$2:$E$1001,"<="&DATE(2026,12,31))) | Q10: =IF($A10="","",H10) | R10: =IF($A10="","",COUNTIFS('SEMINARI BIARA'!$C$2:$C$1001,$A10,'SEMINARI BIARA'!$F$2:$F$1001,"Mulai masuk 2026",'SEMINARI BIARA'!$G$2:$G$1001,">="&DATE(2026,1,1),'SEMINARI BIARA'!$G$2:$G$1001,"<="&DATE(2026,12,31))) | S10: =IF($A10="","",COUNTIFS('SEMINARI BIARA'!$C$2:$C$1001,$A10,'SEMINARI BIARA'!$F$2:$F$1001,"Sedang belajar 2026"))
B11: =IF($A11="","",COUNTIF('DATA KK'!$E$2:$E$501,$A11)) | C11: =IF($A11="","",COUNTIF('DATA UMAT'!$H$2:$H$2001,$A11)) | D11: =IF($A11="","",COUNTIFS(BAPTIS!$C$2:$C$1001,$A11,BAPTIS!$F$2:$F$1001,">="&DATE(2026,1,1),BAPTIS!$F$2:$F$1001,"<="&DATE(2026,12,31))) | E11: =IF($A11="","",COUNTIFS('DITERIMA MASUK'!$C$2:$C$1001,$A11,'DITERIMA MASUK'!$D$2:$D$1001,">="&DATE(2026,1,1),'DITERIMA MASUK'!$D$2:$D$1001,"<="&DATE(2026,12,31))) | F11: =IF($A11="","",COUNTIFS(MUTASI!$C$2:$C$1001,$A11,MUTASI!$D$2:$D$1001,"Masuk",MUTASI!$F$2:$F$1001,"Paroki lain dalam keuskupan",MUTASI!$E$2:$E$1001,">="&DATE(2026,1,1),MUTASI!$E$2:$E$1001,"<="&DATE(2026,12,31))) | G11: =IF($A11="","",COUNTIFS(MUTASI!$C$2:$C$1001,$A11,MUTASI!$D$2:$D$1001,"Masuk",MUTASI!$F$2:$F$1001,"Keuskupan lain",MUTASI!$E$2:$E$1001,">="&DATE(2026,1,1),MUTASI!$E$2:$E$1001,"<="&DATE(2026,12,31))) | H11: =IF($A11="","",COUNTIFS(KEMATIAN!$C$2:$C$1001,$A11,KEMATIAN!$F$2:$F$1001,">="&DATE(2026,1,1),KEMATIAN!$F$2:$F$1001,"<="&DATE(2026,12,31))) | I11: =IF($A11="","",COUNTIFS(MUTASI!$C$2:$C$1001,$A11,MUTASI!$D$2:$D$1001,"Keluar",MUTASI!$F$2:$F$1001,"Paroki lain dalam keuskupan",MUTASI!$E$2:$E$1001,">="&DATE(2026,1,1),MUTASI!$E$2:$E$1001,"<="&DATE(2026,12,31))) | J11: =IF($A11="","",COUNTIFS(MUTASI!$C$2:$C$1001,$A11,MUTASI!$D$2:$D$1001,"Keluar",MUTASI!$F$2:$F$1001,"Keuskupan lain",MUTASI!$E$2:$E$1001,">="&DATE(2026,1,1),MUTASI!$E$2:$E$1001,"<="&DATE(2026,12,31))) | K11: =IF($A11="","",COUNTIFS('PINDAH AGAMA'!$C$2:$C$1001,$A11,'PINDAH AGAMA'!$D$2:$D$1001,">="&DATE(2026,1,1),'PINDAH AGAMA'!$D$2:$D$1001,"<="&DATE(2026,12,31))) | L11: =IF($A11="","",D11+E11+F11+G11-H11-I11-J11-K11) | M11: =IF($A11="","",COUNTIFS('KOMUNI PERTAMA'!$C$2:$C$1001,$A11,'KOMUNI PERTAMA'!$E$2:$E$1001,">="&DATE(2026,1,1),'KOMUNI PERTAMA'!$E$2:$E$1001,"<="&DATE(2026,12,31))) | N11: =IF($A11="","",COUNTIFS('PERKAWINAN GEREJANI'!$C$2:$C$1001,$A11,'PERKAWINAN GEREJANI'!$D$2:$D$1001,">="&DATE(2026,1,1),'PERKAWINAN GEREJANI'!$D$2:$D$1001,"<="&DATE(2026,12,31))) | O11: =IF($A11="","",COUNTIFS(PEMBUBARAN!$C$2:$C$1001,$A11,PEMBUBARAN!$D$2:$D$1001,">="&DATE(2026,1,1),PEMBUBARAN!$D$2:$D$1001,"<="&DATE(2026,12,31))) | P11: =IF($A11="","",COUNTIFS('PERMINYAKAN SUCI'!$C$2:$C$1001,$A11,'PERMINYAKAN SUCI'!$E$2:$E$1001,">="&DATE(2026,1,1),'PERMINYAKAN SUCI'!$E$2:$E$1001,"<="&DATE(2026,12,31))) | Q11: =IF($A11="","",H11) | R11: =IF($A11="","",COUNTIFS('SEMINARI BIARA'!$C$2:$C$1001,$A11,'SEMINARI BIARA'!$F$2:$F$1001,"Mulai masuk 2026",'SEMINARI BIARA'!$G$2:$G$1001,">="&DATE(2026,1,1),'SEMINARI BIARA'!$G$2:$G$1001,"<="&DATE(2026,12,31))) | S11: =IF($A11="","",COUNTIFS('SEMINARI BIARA'!$C$2:$C$1001,$A11,'SEMINARI BIARA'!$F$2:$F$1001,"Sedang belajar 2026"))
B12: =IF($A12="","",COUNTIF('DATA KK'!$E$2:$E$501,$A12)) | C12: =IF($A12="","",COUNTIF('DATA UMAT'!$H$2:$H$2001,$A12)) | D12: =IF($A12="","",COUNTIFS(BAPTIS!$C$2:$C$1001,$A12,BAPTIS!$F$2:$F$1001,">="&DATE(2026,1,1),BAPTIS!$F$2:$F$1001,"<="&DATE(2026,12,31))) | E12: =IF($A12="","",COUNTIFS('DITERIMA MASUK'!$C$2:$C$1001,$A12,'DITERIMA MASUK'!$D$2:$D$1001,">="&DATE(2026,1,1),'DITERIMA MASUK'!$D$2:$D$1001,"<="&DATE(2026,12,31))) | F12: =IF($A12="","",COUNTIFS(MUTASI!$C$2:$C$1001,$A12,MUTASI!$D$2:$D$1001,"Masuk",MUTASI!$F$2:$F$1001,"Paroki lain dalam keuskupan",MUTASI!$E$2:$E$1001,">="&DATE(2026,1,1),MUTASI!$E$2:$E$1001,"<="&DATE(2026,12,31))) | G12: =IF($A12="","",COUNTIFS(MUTASI!$C$2:$C$1001,$A12,MUTASI!$D$2:$D$1001,"Masuk",MUTASI!$F$2:$F$1001,"Keuskupan lain",MUTASI!$E$2:$E$1001,">="&DATE(2026,1,1),MUTASI!$E$2:$E$1001,"<="&DATE(2026,12,31))) | H12: =IF($A12="","",COUNTIFS(KEMATIAN!$C$2:$C$1001,$A12,KEMATIAN!$F$2:$F$1001,">="&DATE(2026,1,1),KEMATIAN!$F$2:$F$1001,"<="&DATE(2026,12,31))) | I12: =IF($A12="","",COUNTIFS(MUTASI!$C$2:$C$1001,$A12,MUTASI!$D$2:$D$1001,"Keluar",MUTASI!$F$2:$F$1001,"Paroki lain dalam keuskupan",MUTASI!$E$2:$E$1001,">="&DATE(2026,1,1),MUTASI!$E$2:$E$1001,"<="&DATE(2026,12,31))) | J12: =IF($A12="","",COUNTIFS(MUTASI!$C$2:$C$1001,$A12,MUTASI!$D$2:$D$1001,"Keluar",MUTASI!$F$2:$F$1001,"Keuskupan lain",MUTASI!$E$2:$E$1001,">="&DATE(2026,1,1),MUTASI!$E$2:$E$1001,"<="&DATE(2026,12,31))) | K12: =IF($A12="","",COUNTIFS('PINDAH AGAMA'!$C$2:$C$1001,$A12,'PINDAH AGAMA'!$D$2:$D$1001,">="&DATE(2026,1,1),'PINDAH AGAMA'!$D$2:$D$1001,"<="&DATE(2026,12,31))) | L12: =IF($A12="","",D12+E12+F12+G12-H12-I12-J12-K12) | M12: =IF($A12="","",COUNTIFS('KOMUNI PERTAMA'!$C$2:$C$1001,$A12,'KOMUNI PERTAMA'!$E$2:$E$1001,">="&DATE(2026,1,1),'KOMUNI PERTAMA'!$E$2:$E$1001,"<="&DATE(2026,12,31))) | N12: =IF($A12="","",COUNTIFS('PERKAWINAN GEREJANI'!$C$2:$C$1001,$A12,'PERKAWINAN GEREJANI'!$D$2:$D$1001,">="&DATE(2026,1,1),'PERKAWINAN GEREJANI'!$D$2:$D$1001,"<="&DATE(2026,12,31))) | O12: =IF($A12="","",COUNTIFS(PEMBUBARAN!$C$2:$C$1001,$A12,PEMBUBARAN!$D$2:$D$1001,">="&DATE(2026,1,1),PEMBUBARAN!$D$2:$D$1001,"<="&DATE(2026,12,31))) | P12: =IF($A12="","",COUNTIFS('PERMINYAKAN SUCI'!$C$2:$C$1001,$A12,'PERMINYAKAN SUCI'!$E$2:$E$1001,">="&DATE(2026,1,1),'PERMINYAKAN SUCI'!$E$2:$E$1001,"<="&DATE(2026,12,31))) | Q12: =IF($A12="","",H12) | R12: =IF($A12="","",COUNTIFS('SEMINARI BIARA'!$C$2:$C$1001,$A12,'SEMINARI BIARA'!$F$2:$F$1001,"Mulai masuk 2026",'SEMINARI BIARA'!$G$2:$G$1001,">="&DATE(2026,1,1),'SEMINARI BIARA'!$G$2:$G$1001,"<="&DATE(2026,12,31))) | S12: =IF($A12="","",COUNTIFS('SEMINARI BIARA'!$C$2:$C$1001,$A12,'SEMINARI BIARA'!$F$2:$F$1001,"Sedang belajar 2026"))
B13: =IF($A13="","",COUNTIF('DATA KK'!$E$2:$E$501,$A13)) | C13: =IF($A13="","",COUNTIF('DATA UMAT'!$H$2:$H$2001,$A13)) | D13: =IF($A13="","",COUNTIFS(BAPTIS!$C$2:$C$1001,$A13,BAPTIS!$F$2:$F$1001,">="&DATE(2026,1,1),BAPTIS!$F$2:$F$1001,"<="&DATE(2026,12,31))) | E13: =IF($A13="","",COUNTIFS('DITERIMA MASUK'!$C$2:$C$1001,$A13,'DITERIMA MASUK'!$D$2:$D$1001,">="&DATE(2026,1,1),'DITERIMA MASUK'!$D$2:$D$1001,"<="&DATE(2026,12,31))) | F13: =IF($A13="","",COUNTIFS(MUTASI!$C$2:$C$1001,$A13,MUTASI!$D$2:$D$1001,"Masuk",MUTASI!$F$2:$F$1001,"Paroki lain dalam keuskupan",MUTASI!$E$2:$E$1001,">="&DATE(2026,1,1),MUTASI!$E$2:$E$1001,"<="&DATE(2026,12,31))) | G13: =IF($A13="","",COUNTIFS(MUTASI!$C$2:$C$1001,$A13,MUTASI!$D$2:$D$1001,"Masuk",MUTASI!$F$2:$F$1001,"Keuskupan lain",MUTASI!$E$2:$E$1001,">="&DATE(2026,1,1),MUTASI!$E$2:$E$1001,"<="&DATE(2026,12,31))) | H13: =IF($A13="","",COUNTIFS(KEMATIAN!$C$2:$C$1001,$A13,KEMATIAN!$F$2:$F$1001,">="&DATE(2026,1,1),KEMATIAN!$F$2:$F$1001,"<="&DATE(2026,12,31))) | I13: =IF($A13="","",COUNTIFS(MUTASI!$C$2:$C$1001,$A13,MUTASI!$D$2:$D$1001,"Keluar",MUTASI!$F$2:$F$1001,"Paroki lain dalam keuskupan",MUTASI!$E$2:$E$1001,">="&DATE(2026,1,1),MUTASI!$E$2:$E$1001,"<="&DATE(2026,12,31))) | J13: =IF($A13="","",COUNTIFS(MUTASI!$C$2:$C$1001,$A13,MUTASI!$D$2:$D$1001,"Keluar",MUTASI!$F$2:$F$1001,"Keuskupan lain",MUTASI!$E$2:$E$1001,">="&DATE(2026,1,1),MUTASI!$E$2:$E$1001,"<="&DATE(2026,12,31))) | K13: =IF($A13="","",COUNTIFS('PINDAH AGAMA'!$C$2:$C$1001,$A13,'PINDAH AGAMA'!$D$2:$D$1001,">="&DATE(2026,1,1),'PINDAH AGAMA'!$D$2:$D$1001,"<="&DATE(2026,12,31))) | L13: =IF($A13="","",D13+E13+F13+G13-H13-I13-J13-K13) | M13: =IF($A13="","",COUNTIFS('KOMUNI PERTAMA'!$C$2:$C$1001,$A13,'KOMUNI PERTAMA'!$E$2:$E$1001,">="&DATE(2026,1,1),'KOMUNI PERTAMA'!$E$2:$E$1001,"<="&DATE(2026,12,31))) | N13: =IF($A13="","",COUNTIFS('PERKAWINAN GEREJANI'!$C$2:$C$1001,$A13,'PERKAWINAN GEREJANI'!$D$2:$D$1001,">="&DATE(2026,1,1),'PERKAWINAN GEREJANI'!$D$2:$D$1001,"<="&DATE(2026,12,31))) | O13: =IF($A13="","",COUNTIFS(PEMBUBARAN!$C$2:$C$1001,$A13,PEMBUBARAN!$D$2:$D$1001,">="&DATE(2026,1,1),PEMBUBARAN!$D$2:$D$1001,"<="&DATE(2026,12,31))) | P13: =IF($A13="","",COUNTIFS('PERMINYAKAN SUCI'!$C$2:$C$1001,$A13,'PERMINYAKAN SUCI'!$E$2:$E$1001,">="&DATE(2026,1,1),'PERMINYAKAN SUCI'!$E$2:$E$1001,"<="&DATE(2026,12,31))) | Q13: =IF($A13="","",H13) | R13: =IF($A13="","",COUNTIFS('SEMINARI BIARA'!$C$2:$C$1001,$A13,'SEMINARI BIARA'!$F$2:$F$1001,"Mulai masuk 2026",'SEMINARI BIARA'!$G$2:$G$1001,">="&DATE(2026,1,1),'SEMINARI BIARA'!$G$2:$G$1001,"<="&DATE(2026,12,31))) | S13: =IF($A13="","",COUNTIFS('SEMINARI BIARA'!$C$2:$C$1001,$A13,'SEMINARI BIARA'!$F$2:$F$1001,"Sedang belajar 2026"))
B14: =IF($A14="","",COUNTIF('DATA KK'!$E$2:$E$501,$A14)) | C14: =IF($A14="","",COUNTIF('DATA UMAT'!$H$2:$H$2001,$A14)) | D14: =IF($A14="","",COUNTIFS(BAPTIS!$C$2:$C$1001,$A14,BAPTIS!$F$2:$F$1001,">="&DATE(2026,1,1),BAPTIS!$F$2:$F$1001,"<="&DATE(2026,12,31))) | E14: =IF($A14="","",COUNTIFS('DITERIMA MASUK'!$C$2:$C$1001,$A14,'DITERIMA MASUK'!$D$2:$D$1001,">="&DATE(2026,1,1),'DITERIMA MASUK'!$D$2:$D$1001,"<="&DATE(2026,12,31))) | F14: =IF($A14="","",COUNTIFS(MUTASI!$C$2:$C$1001,$A14,MUTASI!$D$2:$D$1001,"Masuk",MUTASI!$F$2:$F$1001,"Paroki lain dalam keuskupan",MUTASI!$E$2:$E$1001,">="&DATE(2026,1,1),MUTASI!$E$2:$E$1001,"<="&DATE(2026,12,31))) | G14: =IF($A14="","",COUNTIFS(MUTASI!$C$2:$C$1001,$A14,MUTASI!$D$2:$D$1001,"Masuk",MUTASI!$F$2:$F$1001,"Keuskupan lain",MUTASI!$E$2:$E$1001,">="&DATE(2026,1,1),MUTASI!$E$2:$E$1001,"<="&DATE(2026,12,31))) | H14: =IF($A14="","",COUNTIFS(KEMATIAN!$C$2:$C$1001,$A14,KEMATIAN!$F$2:$F$1001,">="&DATE(2026,1,1),KEMATIAN!$F$2:$F$1001,"<="&DATE(2026,12,31))) | I14: =IF($A14="","",COUNTIFS(MUTASI!$C$2:$C$1001,$A14,MUTASI!$D$2:$D$1001,"Keluar",MUTASI!$F$2:$F$1001,"Paroki lain dalam keuskupan",MUTASI!$E$2:$E$1001,">="&DATE(2026,1,1),MUTASI!$E$2:$E$1001,"<="&DATE(2026,12,31))) | J14: =IF($A14="","",COUNTIFS(MUTASI!$C$2:$C$1001,$A14,MUTASI!$D$2:$D$1001,"Keluar",MUTASI!$F$2:$F$1001,"Keuskupan lain",MUTASI!$E$2:$E$1001,">="&DATE(2026,1,1),MUTASI!$E$2:$E$1001,"<="&DATE(2026,12,31))) | K14: =IF($A14="","",COUNTIFS('PINDAH AGAMA'!$C$2:$C$1001,$A14,'PINDAH AGAMA'!$D$2:$D$1001,">="&DATE(2026,1,1),'PINDAH AGAMA'!$D$2:$D$1001,"<="&DATE(2026,12,31))) | L14: =IF($A14="","",D14+E14+F14+G14-H14-I14-J14-K14) | M14: =IF($A14="","",COUNTIFS('KOMUNI PERTAMA'!$C$2:$C$1001,$A14,'KOMUNI PERTAMA'!$E$2:$E$1001,">="&DATE(2026,1,1),'KOMUNI PERTAMA'!$E$2:$E$1001,"<="&DATE(2026,12,31))) | N14: =IF($A14="","",COUNTIFS('PERKAWINAN GEREJANI'!$C$2:$C$1001,$A14,'PERKAWINAN GEREJANI'!$D$2:$D$1001,">="&DATE(2026,1,1),'PERKAWINAN GEREJANI'!$D$2:$D$1001,"<="&DATE(2026,12,31))) | O14: =IF($A14="","",COUNTIFS(PEMBUBARAN!$C$2:$C$1001,$A14,PEMBUBARAN!$D$2:$D$1001,">="&DATE(2026,1,1),PEMBUBARAN!$D$2:$D$1001,"<="&DATE(2026,12,31))) | P14: =IF($A14="","",COUNTIFS('PERMINYAKAN SUCI'!$C$2:$C$1001,$A14,'PERMINYAKAN SUCI'!$E$2:$E$1001,">="&DATE(2026,1,1),'PERMINYAKAN SUCI'!$E$2:$E$1001,"<="&DATE(2026,12,31))) | Q14: =IF($A14="","",H14) | R14: =IF($A14="","",COUNTIFS('SEMINARI BIARA'!$C$2:$C$1001,$A14,'SEMINARI BIARA'!$F$2:$F$1001,"Mulai masuk 2026",'SEMINARI BIARA'!$G$2:$G$1001,">="&DATE(2026,1,1),'SEMINARI BIARA'!$G$2:$G$1001,"<="&DATE(2026,12,31))) | S14: =IF($A14="","",COUNTIFS('SEMINARI BIARA'!$C$2:$C$1001,$A14,'SEMINARI BIARA'!$F$2:$F$1001,"Sedang belajar 2026"))
B15: =IF($A15="","",COUNTIF('DATA KK'!$E$2:$E$501,$A15)) | C15: =IF($A15="","",COUNTIF('DATA UMAT'!$H$2:$H$2001,$A15)) | D15: =IF($A15="","",COUNTIFS(BAPTIS!$C$2:$C$1001,$A15,BAPTIS!$F$2:$F$1001,">="&DATE(2026,1,1),BAPTIS!$F$2:$F$1001,"<="&DATE(2026,12,31))) | E15: =IF($A15="","",COUNTIFS('DITERIMA MASUK'!$C$2:$C$1001,$A15,'DITERIMA MASUK'!$D$2:$D$1001,">="&DATE(2026,1,1),'DITERIMA MASUK'!$D$2:$D$1001,"<="&DATE(2026,12,31))) | F15: =IF($A15="","",COUNTIFS(MUTASI!$C$2:$C$1001,$A15,MUTASI!$D$2:$D$1001,"Masuk",MUTASI!$F$2:$F$1001,"Paroki lain dalam keuskupan",MUTASI!$E$2:$E$1001,">="&DATE(2026,1,1),MUTASI!$E$2:$E$1001,"<="&DATE(2026,12,31))) | G15: =IF($A15="","",COUNTIFS(MUTASI!$C$2:$C$1001,$A15,MUTASI!$D$2:$D$1001,"Masuk",MUTASI!$F$2:$F$1001,"Keuskupan lain",MUTASI!$E$2:$E$1001,">="&DATE(2026,1,1),MUTASI!$E$2:$E$1001,"<="&DATE(2026,12,31))) | H15: =IF($A15="","",COUNTIFS(KEMATIAN!$C$2:$C$1001,$A15,KEMATIAN!$F$2:$F$1001,">="&DATE(2026,1,1),KEMATIAN!$F$2:$F$1001,"<="&DATE(2026,12,31))) | I15: =IF($A15="","",COUNTIFS(MUTASI!$C$2:$C$1001,$A15,MUTASI!$D$2:$D$1001,"Keluar",MUTASI!$F$2:$F$1001,"Paroki lain dalam keuskupan",MUTASI!$E$2:$E$1001,">="&DATE(2026,1,1),MUTASI!$E$2:$E$1001,"<="&DATE(2026,12,31))) | J15: =IF($A15="","",COUNTIFS(MUTASI!$C$2:$C$1001,$A15,MUTASI!$D$2:$D$1001,"Keluar",MUTASI!$F$2:$F$1001,"Keuskupan lain",MUTASI!$E$2:$E$1001,">="&DATE(2026,1,1),MUTASI!$E$2:$E$1001,"<="&DATE(2026,12,31))) | K15: =IF($A15="","",COUNTIFS('PINDAH AGAMA'!$C$2:$C$1001,$A15,'PINDAH AGAMA'!$D$2:$D$1001,">="&DATE(2026,1,1),'PINDAH AGAMA'!$D$2:$D$1001,"<="&DATE(2026,12,31))) | L15: =IF($A15="","",D15+E15+F15+G15-H15-I15-J15-K15) | M15: =IF($A15="","",COUNTIFS('KOMUNI PERTAMA'!$C$2:$C$1001,$A15,'KOMUNI PERTAMA'!$E$2:$E$1001,">="&DATE(2026,1,1),'KOMUNI PERTAMA'!$E$2:$E$1001,"<="&DATE(2026,12,31))) | N15: =IF($A15="","",COUNTIFS('PERKAWINAN GEREJANI'!$C$2:$C$1001,$A15,'PERKAWINAN GEREJANI'!$D$2:$D$1001,">="&DATE(2026,1,1),'PERKAWINAN GEREJANI'!$D$2:$D$1001,"<="&DATE(2026,12,31))) | O15: =IF($A15="","",COUNTIFS(PEMBUBARAN!$C$2:$C$1001,$A15,PEMBUBARAN!$D$2:$D$1001,">="&DATE(2026,1,1),PEMBUBARAN!$D$2:$D$1001,"<="&DATE(2026,12,31))) | P15: =IF($A15="","",COUNTIFS('PERMINYAKAN SUCI'!$C$2:$C$1001,$A15,'PERMINYAKAN SUCI'!$E$2:$E$1001,">="&DATE(2026,1,1),'PERMINYAKAN SUCI'!$E$2:$E$1001,"<="&DATE(2026,12,31))) | Q15: =IF($A15="","",H15) | R15: =IF($A15="","",COUNTIFS('SEMINARI BIARA'!$C$2:$C$1001,$A15,'SEMINARI BIARA'!$F$2:$F$1001,"Mulai masuk 2026",'SEMINARI BIARA'!$G$2:$G$1001,">="&DATE(2026,1,1),'SEMINARI BIARA'!$G$2:$G$1001,"<="&DATE(2026,12,31))) | S15: =IF($A15="","",COUNTIFS('SEMINARI BIARA'!$C$2:$C$1001,$A15,'SEMINARI BIARA'!$F$2:$F$1001,"Sedang belajar 2026"))
B16: =IF($A16="","",COUNTIF('DATA KK'!$E$2:$E$501,$A16)) | C16: =IF($A16="","",COUNTIF('DATA UMAT'!$H$2:$H$2001,$A16)) | D16: =IF($A16="","",COUNTIFS(BAPTIS!$C$2:$C$1001,$A16,BAPTIS!$F$2:$F$1001,">="&DATE(2026,1,1),BAPTIS!$F$2:$F$1001,"<="&DATE(2026,12,31))) | E16: =IF($A16="","",COUNTIFS('DITERIMA MASUK'!$C$2:$C$1001,$A16,'DITERIMA MASUK'!$D$2:$D$1001,">="&DATE(2026,1,1),'DITERIMA MASUK'!$D$2:$D$1001,"<="&DATE(2026,12,31))) | F16: =IF($A16="","",COUNTIFS(MUTASI!$C$2:$C$1001,$A16,MUTASI!$D$2:$D$1001,"Masuk",MUTASI!$F$2:$F$1001,"Paroki lain dalam keuskupan",MUTASI!$E$2:$E$1001,">="&DATE(2026,1,1),MUTASI!$E$2:$E$1001,"<="&DATE(2026,12,31))) | G16: =IF($A16="","",COUNTIFS(MUTASI!$C$2:$C$1001,$A16,MUTASI!$D$2:$D$1001,"Masuk",MUTASI!$F$2:$F$1001,"Keuskupan lain",MUTASI!$E$2:$E$1001,">="&DATE(2026,1,1),MUTASI!$E$2:$E$1001,"<="&DATE(2026,12,31))) | H16: =IF($A16="","",COUNTIFS(KEMATIAN!$C$2:$C$1001,$A16,KEMATIAN!$F$2:$F$1001,">="&DATE(2026,1,1),KEMATIAN!$F$2:$F$1001,"<="&DATE(2026,12,31))) | I16: =IF($A16="","",COUNTIFS(MUTASI!$C$2:$C$1001,$A16,MUTASI!$D$2:$D$1001,"Keluar",MUTASI!$F$2:$F$1001,"Paroki lain dalam keuskupan",MUTASI!$E$2:$E$1001,">="&DATE(2026,1,1),MUTASI!$E$2:$E$1001,"<="&DATE(2026,12,31))) | J16: =IF($A16="","",COUNTIFS(MUTASI!$C$2:$C$1001,$A16,MUTASI!$D$2:$D$1001,"Keluar",MUTASI!$F$2:$F$1001,"Keuskupan lain",MUTASI!$E$2:$E$1001,">="&DATE(2026,1,1),MUTASI!$E$2:$E$1001,"<="&DATE(2026,12,31))) | K16: =IF($A16="","",COUNTIFS('PINDAH AGAMA'!$C$2:$C$1001,$A16,'PINDAH AGAMA'!$D$2:$D$1001,">="&DATE(2026,1,1),'PINDAH AGAMA'!$D$2:$D$1001,"<="&DATE(2026,12,31))) | L16: =IF($A16="","",D16+E16+F16+G16-H16-I16-J16-K16) | M16: =IF($A16="","",COUNTIFS('KOMUNI PERTAMA'!$C$2:$C$1001,$A16,'KOMUNI PERTAMA'!$E$2:$E$1001,">="&DATE(2026,1,1),'KOMUNI PERTAMA'!$E$2:$E$1001,"<="&DATE(2026,12,31))) | N16: =IF($A16="","",COUNTIFS('PERKAWINAN GEREJANI'!$C$2:$C$1001,$A16,'PERKAWINAN GEREJANI'!$D$2:$D$1001,">="&DATE(2026,1,1),'PERKAWINAN GEREJANI'!$D$2:$D$1001,"<="&DATE(2026,12,31))) | O16: =IF($A16="","",COUNTIFS(PEMBUBARAN!$C$2:$C$1001,$A16,PEMBUBARAN!$D$2:$D$1001,">="&DATE(2026,1,1),PEMBUBARAN!$D$2:$D$1001,"<="&DATE(2026,12,31))) | P16: =IF($A16="","",COUNTIFS('PERMINYAKAN SUCI'!$C$2:$C$1001,$A16,'PERMINYAKAN SUCI'!$E$2:$E$1001,">="&DATE(2026,1,1),'PERMINYAKAN SUCI'!$E$2:$E$1001,"<="&DATE(2026,12,31))) | Q16: =IF($A16="","",H16) | R16: =IF($A16="","",COUNTIFS('SEMINARI BIARA'!$C$2:$C$1001,$A16,'SEMINARI BIARA'!$F$2:$F$1001,"Mulai masuk 2026",'SEMINARI BIARA'!$G$2:$G$1001,">="&DATE(2026,1,1),'SEMINARI BIARA'!$G$2:$G$1001,"<="&DATE(2026,12,31))) | S16: =IF($A16="","",COUNTIFS('SEMINARI BIARA'!$C$2:$C$1001,$A16,'SEMINARI BIARA'!$F$2:$F$1001,"Sedang belajar 2026"))
... B104: =IF($A104="","",COUNTIF('DATA KK'!$E$2:$E$501,$A104)) | C104: =IF($A104="","",COUNTIF('DATA UMAT'!$H$2:$H$2001,$A104)) | D104: =IF($A104="","",COUNTIFS(BAPTIS!$C$2:$C$1001,$A104,BAPTIS!$F$2:$F$1001,">="&DATE(2026,1,1),BAPTIS!$F$2:$F$1001,"<="&DATE(2026,12,31))) | E104: =IF($A104="","",COUNTIFS('DITERIMA MASUK'!$C$2:$C$1001,$A104,'DITERIMA MASUK'!$D$2:$D$1001,">="&DATE(2026,1,1),'DITERIMA MASUK'!$D$2:$D$1001,"<="&DATE(2026,12,31))) | F104: =IF($A104="","",COUNTIFS(MUTASI!$C$2:$C$1001,$A104,MUTASI!$D$2:$D$1001,"Masuk",MUTASI!$F$2:$F$1001,"Paroki lain dalam keuskupan",MUTASI!$E$2:$E$1001,">="&DATE(2026,1,1),MUTASI!$E$2:$E$1001,"<="&DATE(2026,12,31))) | G104: =IF($A104="","",COUNTIFS(MUTASI!$C$2:$C$1001,$A104,MUTASI!$D$2:$D$1001,"Masuk",MUTASI!$F$2:$F$1001,"Keuskupan lain",MUTASI!$E$2:$E$1001,">="&DATE(2026,1,1),MUTASI!$E$2:$E$1001,"<="&DATE(2026,12,31))) | H104: =IF($A104="","",COUNTIFS(KEMATIAN!$C$2:$C$1001,$A104,KEMATIAN!$F$2:$F$1001,">="&DATE(2026,1,1),KEMATIAN!$F$2:$F$1001,"<="&DATE(2026,12,31))) | I104: =IF($A104="","",COUNTIFS(MUTASI!$C$2:$C$1001,$A104,MUTASI!$D$2:$D$1001,"Keluar",MUTASI!$F$2:$F$1001,"Paroki lain dalam keuskupan",MUTASI!$E$2:$E$1001,">="&DATE(2026,1,1),MUTASI!$E$2:$E$1001,"<="&DATE(2026,12,31))) | J104: =IF($A104="","",COUNTIFS(MUTASI!$C$2:$C$1001,$A104,MUTASI!$D$2:$D$1001,"Keluar",MUTASI!$F$2:$F$1001,"Keuskupan lain",MUTASI!$E$2:$E$1001,">="&DATE(2026,1,1),MUTASI!$E$2:$E$1001,"<="&DATE(2026,12,31))) | K104: =IF($A104="","",COUNTIFS('PINDAH AGAMA'!$C$2:$C$1001,$A104,'PINDAH AGAMA'!$D$2:$D$1001,">="&DATE(2026,1,1),'PINDAH AGAMA'!$D$2:$D$1001,"<="&DATE(2026,12,31))) | L104: =IF($A104="","",D104+E104+F104+G104-H104-I104-J104-K104) | M104: =IF($A104="","",COUNTIFS('KOMUNI PERTAMA'!$C$2:$C$1001,$A104,'KOMUNI PERTAMA'!$E$2:$E$1001,">="&DATE(2026,1,1),'KOMUNI PERTAMA'!$E$2:$E$1001,"<="&DATE(2026,12,31))) | N104: =IF($A104="","",COUNTIFS('PERKAWINAN GEREJANI'!$C$2:$C$1001,$A104,'PERKAWINAN GEREJANI'!$D$2:$D$1001,">="&DATE(2026,1,1),'PERKAWINAN GEREJANI'!$D$2:$D$1001,"<="&DATE(2026,12,31))) | O104: =IF($A104="","",COUNTIFS(PEMBUBARAN!$C$2:$C$1001,$A104,PEMBUBARAN!$D$2:$D$1001,">="&DATE(2026,1,1),PEMBUBARAN!$D$2:$D$1001,"<="&DATE(2026,12,31))) | P104: =IF($A104="","",COUNTIFS('PERMINYAKAN SUCI'!$C$2:$C$1001,$A104,'PERMINYAKAN SUCI'!$E$2:$E$1001,">="&DATE(2026,1,1),'PERMINYAKAN SUCI'!$E$2:$E$1001,"<="&DATE(2026,12,31))) | Q104: =IF($A104="","",H104) | R104: =IF($A104="","",COUNTIFS('SEMINARI BIARA'!$C$2:$C$1001,$A104,'SEMINARI BIARA'!$F$2:$F$1001,"Mulai masuk 2026",'SEMINARI BIARA'!$G$2:$G$1001,">="&DATE(2026,1,1),'SEMINARI BIARA'!$G$2:$G$1001,"<="&DATE(2026,12,31))) | S104: =IF($A104="","",COUNTIFS('SEMINARI BIARA'!$C$2:$C$1001,$A104,'SEMINARI BIARA'!$F$2:$F$1001,"Sedang belajar 2026"))
A105: TOTAL PAROKI | B105: =SUM(B5:B104) | C105: =SUM(C5:C104) | D105: =SUM(D5:D104) | E105: =SUM(E5:E104) | F105: =SUM(F5:F104) | G105: =SUM(G5:G104) | H105: =SUM(H5:H104) | I105: =SUM(I5:I104) | ... S105: =SUM(S5:S104)

Sheet REKAP DETAIL
A1: REKAP DETAIL STATISTIK 2026
A3: 2. JUMLAH YANG DIBAPTIS — UMUR & JENIS KELAMIN | F3: 3. PINDAH AGAMA — AGAMA BARU
A4: Kelompok Umur | B4: Pria/Laki-laki | C4: Wanita/Perempuan | D4: Jumlah | F4: Agama Baru | G4: Jumlah
A5: < 1 tahun | B5: =COUNTIFS(BAPTIS!$D$2:$D$1001,"Pria/Laki-laki",BAPTIS!$F$2:$F$1001,">="&DATE(2026,1,1),BAPTIS!$F$2:$F$1001,"<="&DATE(2026,12,31),BAPTIS!$G$2:$G$1001,0) | C5: =COUNTIFS(BAPTIS!$D$2:$D$1001,"Wanita/Perempuan",BAPTIS!$F$2:$F$1001,">="&DATE(2026,1,1),BAPTIS!$F$2:$F$1001,"<="&DATE(2026,12,31),BAPTIS!$G$2:$G$1001,0) | D5: =SUM(B5:C5) | F5: Kristen Lain | G5: =COUNTIFS('PINDAH AGAMA'!$E$2:$E$1001,F5,'PINDAH AGAMA'!$D$2:$D$1001,">="&DATE(2026,1,1),'PINDAH AGAMA'!$D$2:$D$1001,"<="&DATE(2026,12,31))
A6: 1 tahun s/d hampir 7 tahun | B6: =COUNTIFS(BAPTIS!$D$2:$D$1001,"Pria/Laki-laki",BAPTIS!$F$2:$F$1001,">="&DATE(2026,1,1),BAPTIS!$F$2:$F$1001,"<="&DATE(2026,12,31),BAPTIS!$G$2:$G$1001,">=1",BAPTIS!$G$2:$G$1001,"<7") | C6: =COUNTIFS(BAPTIS!$D$2:$D$1001,"Wanita/Perempuan",BAPTIS!$F$2:$F$1001,">="&DATE(2026,1,1),BAPTIS!$F$2:$F$1001,"<="&DATE(2026,12,31),BAPTIS!$G$2:$G$1001,">=1",BAPTIS!$G$2:$G$1001,"<7") | D6: =SUM(B6:C6) | F6: Buddha | G6: =COUNTIFS('PINDAH AGAMA'!$E$2:$E$1001,F6,'PINDAH AGAMA'!$D$2:$D$1001,">="&DATE(2026,1,1),'PINDAH AGAMA'!$D$2:$D$1001,"<="&DATE(2026,12,31))
A7: 7 tahun ke atas | B7: =COUNTIFS(BAPTIS!$D$2:$D$1001,"Pria/Laki-laki",BAPTIS!$F$2:$F$1001,">="&DATE(2026,1,1),BAPTIS!$F$2:$F$1001,"<="&DATE(2026,12,31),BAPTIS!$G$2:$G$1001,">=7") | C7: =COUNTIFS(BAPTIS!$D$2:$D$1001,"Wanita/Perempuan",BAPTIS!$F$2:$F$1001,">="&DATE(2026,1,1),BAPTIS!$F$2:$F$1001,"<="&DATE(2026,12,31),BAPTIS!$G$2:$G$1001,">=7") | D7: =SUM(B7:C7) | F7: Konghucu | G7: =COUNTIFS('PINDAH AGAMA'!$E$2:$E$1001,F7,'PINDAH AGAMA'!$D$2:$D$1001,">="&DATE(2026,1,1),'PINDAH AGAMA'!$D$2:$D$1001,"<="&DATE(2026,12,31))
